Workbook

Sheet Form Responses 1
A1: Timestamp | B1: Email Address | C1: NAME | D1: SEX | E1: DESIGNATION | F1: PAN NUMBER | G1: TAN NUMBER | H1: Phone number | I1: SCHOOL TYPE | J1: SCHOOL NAME | K1: OFFICE ADDRESS | L1: PP | M1: PP SURRENDER | N1: BONUS | O1: BASIC PAY | P1: INCREMENT MONTH | Q1: CCA | R1: HRA | S1: Specially abled Persons transport allowance | T1: SURRENDER | U1: SELECTION GRADE OR SPECIAL GRADE | V1: SELECTION GRADE OR SPECIAL GRADE 2 | W1: IT ADVANCE - MARCH -2025 | X1: IT ADVANCE - APRIL-2025 | Y1: IT ADVANCE - MAY-2025 | Z1: IT ADVANCE - JUNE | AA1: IT ADVANCE - JULY | AB1: IT ADVANCE - AUGUEST | AC1: IT ADVANCE - SEPTEMBER | AD1: IT ADVANCE - OCTOBER | AE1: IT ADVANCE - NOVEMBER | AF1: IT ADVANCE - DECEMBER | AG1: IT ADVANCE - JANUARY - 2026 | AH1: WHATSAPP NUMBER | AI1: STRIKE MONTH | AJ1: ஸ்ட்ரைகில் இருந்த நாட்கள் எண்ணிக்கை மட்டும்
A2: 46061.509 | B2: ctkselvaa@gmail.com | C2: SELVAKUMAR | D2: MALE | E2: S..G.TEACHER | F2: Avtps5522p | G2: Che | H2: 8122440081 | I2: P.U.PRIMARY SCHOOL, | J2: Kottai | K2: Marungapuri | L2: 2000 | M2: 0 | N2: 3000 | O2: 42500 | P2: 10 | Q2: 0 | R2: 1 | S2: 2500 | T2: 11 | U2: 30000 | V2: 6 | W2: 100 | X2: 101 | Y2: 102 | Z2: 103 | AA2: 104 | AB2: 105 | AC2: 106 | AD2: 107 | AE2: 108 | AF2: 109 | AG2: 110 | AH2: 8122440081 | AI2: SENT | AJ2: 25
A3: 46061.548 | B3: smk86be@gmail.com | C3: THATANI P | D3: FEMALE | E3: S..G.TEACHER | F3: AJLPT8545P | G3: CHEA06504B | H3: 9786690350 | I3: P.U.PRIMARY SCHOOL, | J3: PANAYAPURAM | K3: VIKRAVANDI | L3: 2000 | M3: 0 | N3: 0 | O3: 33100 | P3: 10 | Q3: 0 | R3: 1 | S3: 0 | T3: 0 | U3: 0 | V3: 0 | W3: 0 | X3: 0 | Y3: 0 | Z3: 0 | AA3: 0 | AB3: 0 | AC3: 0 | AD3: 0 | AE3: 0 | AF3: 0 | AG3: 0 | AH3: 9600561188 | AI3: SENT | AJ3: 26
A4: 46061.591 | B4: trgeeteedee1988@gmail.com | C4: T.GEETHA | D4: FEMALE | E4: S..G.TEACHER | F4: BMIPG8243A | G4: CHEA11142F | H4: 9865422764 | I4: P.U.PRIMARY SCHOOL, | J4: THENNAMPATTU | K4: BEO OFFICE, VEMBAKKAM | L4: 2000 | M4: 0 | N4: 3000 | O4: 34100 | P4: 10 | Q4: 0 | R4: 3 | S4: 0 | T4: 0 | U4: 0 | V4: 0 | W4: 0 | X4: 0 | Y4: 0 | Z4: 0 | AA4: 0 | AB4: 0 | AC4: 0 | AD4: 0 | AE4: 0 | AF4: 0 | AG4: 0 | AH4: 9865422764 | AI4: SENT | AJ4: 27
A5: 46061.668 | B5: raja.hill67@gmail.com | C5: Raja | D5: MALE | E5: HEADMASTER | F5: AFYPR4036G | G5: 0 | H5: 9842441819 | I5: - | J5: Trichy | K5: 23/A, sannathi street, Irudhayapuram, Palakkarai, Trichy-01 | L5: 0 | M5: 0 | N5: 0 | O5: 85400 | P5: 1 | Q5: 1 | R5: 4 | S5: 0 | T5: 1 | U5: 0 | V5: 0 | W5: 0 | X5: 0 | Y5: 0 | Z5: 10082 | AA5: 0 | AB5: 0 | AC5: 0 | AD5: 0 | AE5: 0 | AF5: 0 | AG5: 0 | AH5: 9842441819 | AI5: SENT | AJ5: 0
A6: 46061.686 | B6: rasuselvarasu5@gmail.com | C6: Selvarasu K | D6: MALE | E6: B.T.ASST | F6: BSBPS8703A | G6: CHEA | H6: 9791112884 | I6: P.U.MIDDLE SCHOOL, | J6: Kodungaiyur | K6: Todiarpet | L6: 0 | M6: 0 | N6: 0 | O6: 78700 | P6: 4 | Q6: 2 | R6: 5 | S6: 0 | T6: 11 | U6: 0 | V6: 0 | W6: 0 | X6: 10323 | Y6: 10676 | Z6: 10676 | AA6: 10676 | AB6: 10675 | AC6: 10676 | AD6: 10675 | AE6: 14559 | AF6: 14643 | AG6: 14643 | AH6: 9791112884 | AI6: SENT | AJ6: 0
A7: 46061.806 | B7: saipands2024@gmail.com | C7: A.PANDIMUNIYAMMAL | D7: FEMALE | E7: S..G.TEACHER | F7: CEHPP2328P | G7: 0 | H7: 8610523138 | I7: - | J7: Corporation middle school, Melavasal No:2,Madurai | K7: Corporation office, Educational Department, Madurai | L7: 2000 | M7: 0 | N7: 3000 | O7: 34100 | P7: 10 | Q7: 1 | R7: 2 | S7: 0 | T7: 1 | U7: 0 | V7: 2 | W7: 0 | X7: 0 | Y7: 0 | Z7: 0 | AA7: 0 | AB7: 0 | AC7: 0 | AD7: 0 | AE7: 0 | AF7: 0 | AG7: 0 | AH7: 8610523138 | AI7: SENT | AJ7: 27
A8: 46061.841 | B8: avmathi34@gmail.com | C8: A.ILAMATHI | D8: FEMALE | E8: S..G.TEACHER | F8: ACYPI2210C | G8: CHEA14148B | H8: 9677614030 | I8: P.U.PRIMARY SCHOOL, | J8: SAMIYADIKUCHIPALAYAM | K8: BEO OFFICE,VIKKIRAVANDI | L8: 2000 | M8: 0 | N8: 3000 | O8: 32100 | P8: 7 | Q8: 0 | R8: 3 | S8: 0 | T8: 10 | AH8: 9677614030 | AI8: SENT | AJ8: 27
A9: 46061.924 | B9: amjose87@gmail.com | C9: A.M.JOSE | D9: MALE | E9: S..G.TEACHER | F9: AVPPJ0637E | G9: CHEA14610B | H9: 9843083017 | I9: P.U.PRIMARY SCHOOL, | J9: SIRUVALAI | K9: BEO OFFICE ,KANAI | L9: 2000 | M9: 0 | N9: 3000 | O9: 36200 | P9: 10 | Q9: 0 | R9: 3 | S9: 0 | T9: 0 | AH9: 9843083017 | AI9: SENT | AJ9: 27
A10: 46061.94 | B10: dhanalakshmi631981@gmail.com | C10: DHANALAKSHMI T | D10: FEMALE | E10: S..G.TEACHER | F10: BZPPD1152F | G10: CMBB05500F | H10: 9976130320 | I10: P.U.MIDDLE SCHOOL, | J10: PALAVANJIPALAYAM | K10: BEO OFFICE, TIRUPUR SOUTH | L10: 2000 | M10: 1000 | N10: 3000 | O10: 30300 | P10: 10 | Q10: 0 | R10: 2 | S10: 0 | T10: 11 | U10: 0 | V10: 0 | W10: 0 | X10: 0 | Y10: 0 | Z10: 0 | AA10: 0 | AB10: 0 | AC10: 0 | AD10: 0 | AE10: 0 | AF10: 0 | AG10: 0 | AH10: 9976130320 | AI10: SENT | AJ10: 22
A11: 46062.343 | B11: velraknaas@gmail.com | C11: V.SANKARAPANDIAN | D11: MALE | E11: B.T.ASST | F11: BUWPS43267 | G11: MARIA01937F | H11: 6374889515 | I11: GOVT.HIGHER SEC. SCHOOL, | J11: Madurai corp | K11: Govt school | L11: 0 | M11: 0 | N11: 3000 | O11: 58600 | P11: 10 | Q11: 0 | R11: 3 | S11: 0 | T11: 11 | AH11: 9840535635 | AI11: SENT | AJ11: 0
A12: 46062.526 | B12: chokkikulamcps@gmail.com | C12: R.VANITHAMANI | D12: FEMALE | E12: S..G.TEACHER | F12: AEAPV2650K | G12: MRIA01937F | H12: 9445908604 | I12: - | J12: CORPORATION PRIMARY SCHOOL,CHOKKIKULAM | K12: MADURAI CORPORATION | L12: 2000 | M12: 0 | N12: 3000 | O12: 67500 | P12: 1 | Q12: 1 | R12: 4 | S12: 0 | T12: 0 | U12: 0 | V12: 0 | W12: 0 | X12: 8320 | Y12: 6856 | Z12: 6856 | AA12: 6856 | AB12: 6854 | AC12: 6854 | AD12: 6854 | AE12: 7487 | AF12: 7487 | AG12: 8214 | AH12: 8668019469 | AI12: SENT | AJ12: 0
A13: 46062.477 | B13: msubalakshmi1205@gmail.com | C13: M.SUBALAKSHMI | D13: FEMALE | E13: S..G.TEACHER | F13: FPNPS6555H | G13: CHEA15725D | H13: 9003577482 | I13: P.U.PRIMARY SCHOOL, | J13: NANNADU | K13: BEO OFFICE, KOLIYANUR. | L13: 2000 | M13: 1000 | N13: 3000 | O13: 36200 | P13: 10 | Q13: 0 | R13: 3 | S13: 0 | T13: 1 | U13: 0 | V13: 0 | W13: 0 | X13: 0 | Y13: 0 | Z13: 0 | AA13: 0 | AB13: 0 | AC13: 0 | AD13: 0 | AE13: 0 | AF13: 0 | AG13: 0 | AH13: 9003577482 | AI13: SENT | AJ13: 27
A14: 46062.488 | B14: kavipalani510@gmail.com | C14: Kavitha.S | D14: FEMALE | E14: S..G.TEACHER | F14: BNGPK2385C | G14: MRIN01937F | H14: 9790504933 | I14: P.U.PRIMARY SCHOOL, | J14: South Veli Street no-1 | K14: CORPORATION | L14: 2000 | M14: 0 | N14: 3000 | O14: 37300 | P14: 7 | Q14: 0 | R14: 2 | S14: 0 | T14: 12 | U14: 0 | V14: 0 | W14: 0 | X14: 0 | Y14: 0 | Z14: 0 | AA14: 0 | AB14: 0 | AC14: 0 | AD14: 0 | AE14: 0 | AF14: 0 | AG14: 0 | AH14: 9790504933 | AI14: SENT | AJ14: 5
A15: 46062.498 | B15: rrajathybagyavathi@gmail.com | C15: Rajathy BAGYAVATHY | D15: FEMALE | E15: S..G.TEACHER | F15: AKGPR2536J | G15: MRIN01937F | H15: 9894736589 | I15: P.U.PRIMARY SCHOOL, | J15: South veli street | K15: Corporation | L15: 2000 | M15: 0 | N15: 3000 | O15: 59900 | P15: 4 | Q15: 1 | R15: 4 | S15: 0 | T15: 12 | U15: 0 | V15: 0 | W15: 0 | X15: 0 | Z15: 0 | AA15: 0 | AB15: 0 | AC15: 0 | AD15: 0 | AE15: 0 | AF15: 9058 | AG15: 10619 | AH15: 9894736589 | AI15: SENT | AJ15: 0
A16: 46062.525 | B16: kathirkathir13893@gmail.com | C16: KALEESWARI C | D16: FEMALE | E16: S..G.TEACHER | F16: BEKPK9225E | G16: MRINO1937F | H16: 9976465015 | I16: P.U.PRIMARY SCHOOL, | J16: South Veli Street No -1 | K16: CORPORATION | L16: 2000 | M16: 0 | N16: 3000 | O16: 53300 | P16: 4 | Q16: 1 | R16: 4 | S16: 0 | T16: 12 | U16: 0 | V16: 0 | W16: 0 | X16: 0 | Y16: 0 | Z16: 0 | AA16: 0 | AB16: 0 | AC16: 0 | AD16: 0 | AE16: 0 | AF16: 0 | AG16: 0 | AH16: 9976465015 | AI16: SENT | AJ16: 0
A17: 46062.506 | B17: mukeshsuvi@gmail.com | C17: NagalakshmiN | D17: FEMALE | E17: S..G.TEACHER | F17: ACPPN2264C | G17: MRIAN01937F | H17: 9655668917 | I17: P.U.PRIMARY SCHOOL, | J17: Southveli street | K17: Corporation | L17: 2000 | M17: 0 | N17: 3000 | O17: 71600 | P17: 7 | Q17: 1 | R17: 4 | S17: 0 | T17: 0 | U17: 0 | V17: 0 | W17: 0 | X17: 7480 | Y17: 7793 | Z17: 7793 | AA17: 8300 | AB17: 8300 | AC17: 8300 | AD17: 8300 | AE17: 8990 | AF17: 8990 | AG17: 9225 | AH17: 9655668917 | AI17: SENT | AJ17: 0
A18: 46062.531 | B18: malarravikumar69@gmail.com | C18: Malarvizhi M | D18: FEMALE | E18: S..G.TEACHER | F18: AJDPM5895R | G18: MRIAN01937F | H18: 9789689699 | I18: P.U.PRIMARY SCHOOL, | J18: Southveli street | K18: Corporation | L18: 2000 | M18: 0 | N18: 3000 | O18: 69500 | P18: 7 | Q18: 1 | R18: 4 | S18: 0 | T18: 0 | U18: 0 | V18: 0 | W18: 0 | X18: 6933 | Y18: 7236 | Z18: 7236 | AA18: 7745 | AB18: 7744 | AC18: 7745 | AD18: 7745 | AE18: 8415 | AF18: 8415 | AG18: 8649 | AH18: 9789689699 | AI18: SENT | AJ18: 0
A19: 46062.523 | B19: kalamani672@gmail.com | C19: KALAMANI A | D19: FEMALE | E19: S..G.TEACHER | F19: BCBPK7981E | G19: MIRNO1937F | H19: 8903620065 | I19: P.U.PRIMARY SCHOOL, | J19: SOUTH VELI STREET NO -1 | K19: CORPORATION | L19: 2000 | M19: 0 | N19: 3000 | O19: 53300 | P19: 4 | Q19: 1 | R19: 4 | S19: 0 | T19: 0 | U19: 0 | V19: 0 | W19: 0 | X19: 0 | Y19: 0 | Z19: 0 | AA19: 0 | AB19: 0 | AC19: 0 | AD19: 0 | AE19: 0 | AF19: 0 | AG19: 0 | AH19: 8903620065 | AI19: SENT | AJ19: 0
A20: 46062.537 | B20: nagajothi.ng@gmail.com | C20: NAGAJOTHI P | D20: FEMALE | E20: S..G.TEACHER | F20: ATFPN8198Q | G20: MRINO1937F | H20: 9025597170 | I20: P.U.PRIMARY SCHOOL, | J20: SOUTH VELI STREET NO-1 | K20: CORPORATION | L20: 2000 | M20: 0 | N20: 3000 | O20: 53300 | P20: 4 | Q20: 1 | R20: 4 | S20: 0 | T20: 1 | U20: 0 | V20: 00 | W20: 0 | X20: 0 | Y20: 0 | Z20: 0 | AA20: 0 | AB20: 0 | AC20: 0 | AD20: 0 | AE20: 0 | AF20: 0 | AG20: 0 | AH20: 9025597170 | AI20: SENT | AJ20: 0
A21: 46062.574 | B21: marasumani69@gmail.com | C21: M.ARASUMANI | D21: FEMALE | E21: HEADMASTER | F21: ADDPA7445G | G21: MARIA01937F | H21: 9994424377 | I21: - | J21: MADURAI | K21: MADURAI CORPORATION | L21: 0 | M21: 0 | N21: 0 | O21: 103200 | P21: 10 | Q21: 1 | R21: 4 | S21: 0 | T21: 1 | U21: 0 | V21: 0 | W21: 18720 | X21: 18720 | Y21: 15607 | Z21: 15607 | AA21: 15607 | AB21: 15607 | AC21: 15607 | AD21: 16607 | AE21: 17919 | AF21: 17919 | AG21: 17919 | AH21: 9994424377 | AI21: SENT | AJ21: 0
A22: 46062.585 | B22: kannanprabha1969@gmail.com | C22: KANNAN D | D22: MALE | E22: HEADMASTER | F22: ALDPK0861F | G22: MRIN01937F | H22: 9360547360 | I22: P.U.PRIMARY SCHOOL, | J22: South veli street | K22: Corporation | L22: 0 | M22: 0 | N22: 0 | O22: 67500 | P22: 10 | Q22: 1 | R22: 4 | S22: 0 | T22: 0 | U22: 0 | V22: 0 | W22: 0 | X22: 2660 | Y22: 4626 | Z22: 4626 | AA22: 4626 | AB22: 4626 | AC22: 4626 | AD22: 7850 | AE22: 10273 | AF22: 10273 | AG22: 10273 | AH22: 9360547360 | AI22: SENT | AJ22: 0
A23: 46062.592 | B23: teacherpunitha12@gmail.com | C23: A. PUNITHA | D23: FEMALE | E23: B.T.ASST | F23: ATLPP9565 | G23: MARI01937F | H23: 8428299993 | I23: - | J23: MADURAI | K23: MADURAI CORPORATION | L23: 0 | M23: 0 | N23: 0 | O23: 60300 | P23: 10 | Q23: 1 | R23: 4 | S23: 0 | T23: 1 | U23: 0 | V23: 0 | W23: 5720 | X23: 5720 | Y23: 0 | Z23: 0 | AA23: 0 | AB23: 0 | AC23: 0 | AD23: 0 | AE23: 0 | AF23: 0 | AG23: 0 | AH23: 8428299992 | AI23: SENT | AJ23: 0
A24: 46062.623 | B24: vragav12@gmail.com | C24: M.VIJAYARAGAVAN | D24: MALE | E24: S..G.TEACHER | F24: APYPV7063D | G24: CHEA06551G | H24: 9600576563 | I24: P.U.PRIMARY SCHOOL, | J24: ANBIL | K24: BEO OFFICE, LALGUDI | L24: 2000 | M24: 1000 | N24: 3000 | O24: 36200 | P24: 10 | Q24: 1 | R24: 4 | S24: 0 | T24: 11 | U24: 0 | V24: 0 | W24: 0 | X24: 0 | Y24: 0 | Z24: 0 | AA24: 0 | AB24: 0 | AC24: 0 | AD24: 0 | AE24: 0 | AF24: 4826 | AG24: 0 | AH24: 9600576563 | AI24: SENT | AJ24: 27
A25: 46062.64 | B25: vidyadarshu087@gmail.com | C25: M. Nagalakshmi | D25: FEMALE | E25: S..G.TEACHER | F25: AVFPN0962Q | G25: CHEA06501F | H25: 9786364808 | I25: P.U.PRIMARY SCHOOL, | J25: Thiruvalarsolai | K25: Pups Thiruvalarsolai | L25: 2000 | M25: 0 | N25: 3000 | O25: 34100 | P25: 1 | Q25: 1 | R25: 2 | S25: 0 | T25: 0 | U25: 0 | V25: 1 | W25: 0 | X25: 0 | Y25: 0 | Z25: 0 | AA25: 0 | AB25: 0 | AC25: 0 | AD25: 0 | AE25: 0 | AF25: 0 | AG25: 0 | AH25: 9786364808 | AI25: SENT | AJ25: 2
A26: 46062.648 | B26: bagyaramm1411@gmail.com | C26: M.BAGYALAKSHMI | D26: FEMALE | E26: S..G.TEACHER | F26: BASPB5561Q | G26: CHEA06551G | H26: 9894370723 | I26: P.U.MIDDLE SCHOOL, | J26: AGALANGANALLUR | K26: BEO OFFICE, LALGUDI | L26: 2000 | M26: 0 | N26: 3000 | O26: 32100 | P26: 10 | Q26: 1 | R26: 4 | S26: 0 | T26: 0 | U26: 0 | V26: 0 | W26: 0 | X26: 0 | Y26: 0 | Z26: 0 | AA26: 0 | AB26: 0 | AC26: 0 | AD26: 0 | AE26: 0 | AF26: 0 | AG26: 0 | AH26: 9894370723 | AI26: SENT | AJ26: 27
A27: 46062.662 | B27: rojamathik@gmail.com | C27: ROJAMATHI.K | D27: FEMALE | E27: S..G.TEACHER | F27: BKPPR5092B | G27: CHEA06551G | H27: 8248206340 | I27: P.U.PRIMARY SCHOOL, | J27: PUDHUR UTHAMANUR | K27: BEO OFFICE, LALGUDI | L27: 2000 | M27: 0 | N27: 3000 | O27: 33100 | P27: 4 | Q27: 1 | R27: 4 | S27: 0 | T27: 0 | U27: 0 | AH27: 8248206340 | AI27: SENT | AJ27: 27
A28: 46064.572 | B28: ruckmaniruckmani147@gmail.com | C28: RUCKMANI.K | D28: FEMALE | E28: S..G.TEACHER | F28: BMGPR4568B | G28: CHEO02881E | H28: 6379744881 | I28: P.U.PRIMARY SCHOOL, | J28: VALADI WEST | K28: BEO OFFICE LALGUDI | L28: 2000 | M28: 0 | N28: 3000 | O28: 36200 | P28: 10 | Q28: 1 | R28: 4 | S28: 0 | T28: 0 | U28: 0 | V28: 0 | W28: 0 | X28: 0 | Y28: 0 | Z28: 0 | AA28: 0 | AB28: 0 | AC28: 0 | AD28: 0 | AE28: 0 | AF28: 0 | AG28: 0 | AH28: 6379744881 | AI28: SENT | AJ28: 27
A29: 46063.46 | B29: vinothpaul1984@gmail.com | C29: D.PAULINE | D29: FEMALE | E29: S..G.TEACHER | F29: BFDPP1551G | G29: MARIA01937F | H29: 7871480675 | I29: - | J29: Corporation Primary School, Munichalai, Madurai | K29: CORPORATION EDUCATIONAL OFFICE | L29: 2000 | M29: 0 | N29: 3000 | O29: 37300 | P29: 7 | Q29: 1 | R29: 3 | S29: 0 | T29: 0 | AH29: 7871480675 | AI29: SENT | AJ29: 27
A30: 46062.659 | B30: ttjanandhi@gmail.com | C30: ANNADHI ,J | D30: FEMALE | E30: S..G.TEACHER | F30: BFOPA4917E | G30: CHEA06551G | H30: 9600303288 | I30: P.U.PRIMARY SCHOOL, | J30: THENGAL | K30: BEO OFFICE LALGUDI | L30: 2000 | M30: 1000 | N30: 3000 | O30: 32100 | P30: 10 | Q30: 1 | R30: 3 | S30: 0 | T30: 12 | U30: 0 | V30: 0 | W30: 0 | X30: 0 | Y30: 0 | Z30: 0 | AA30: 0 | AB30: 0 | AC30: 0 | AD30: 0 | AE30: 0 | AF30: 0 | AG30: 0 | AH30: 9600303288 | AI30: SENT | AJ30: 27
A31: 46063.438 | B31: santhoshnaveen385@gmail.com | C31: DURGA DEVI.P | D31: FEMALE | E31: S..G.TEACHER | F31: BOVPD4856D | G31: MARIA01937F | H31: 9842026923 | I31: - | J31: SHENOY NAGAR | K31: Madurai corporation | L31: 2000 | M31: 0 | N31: 3000 | O31: 37300 | P31: 10 | Q31: 1 | R31: 4 | S31: 0 | T31: 0 | U31: 0 | V31: 0 | W31: 0 | X31: 0 | Y31: 0 | Z31: 0 | AA31: 0 | AB31: 0 | AC31: 0 | AD31: 0 | AE31: 0 | AF31: 0 | AG31: 0 | AH31: 9842026923 | AI31: SENT | AJ31: 27
A32: 46063.446 | B32: emharish15@gmail.com | C32: MARIAMMAL k | D32: FEMALE | E32: S..G.TEACHER | F32: CRUPM4226P | G32: 43020535555 | H32: 8754929271 | I32: P.U.MIDDLE SCHOOL, | J32: Kottiyampoondi | K32: BEO OFFICE, VIKRAVANDI | L32: 2000 | M32: 0 | N32: 3000 | O32: 28500 | P32: 7 | Q32: 0 | R32: 1 | S32: 2500 | T32: 10 | U32: 19737 | V32: 3 | W32: 0 | X32: 0 | Y32: 0 | Z32: 0 | AA32: 0 | AB32: 0 | AC32: 0 | AD32: 0 | AF32: 0 | AG32: 0 | AH32: 6374666907 | AI32: SENT | AJ32: 20
A33: 46063.458 | B33: jeyavanibala@gmail.com | C33: JEYAVANI.P | D33: FEMALE | E33: S..G.TEACHER | F33: AOMPJ3529H | G33: MARIA01937F | H33: 9500250551 | I33: - | J33: Manjanakkara corporation primary school | K33: CORPORATION EDUCATIONAL OFFICE | L33: 2000 | M33: 0 | N33: 3000 | O33: 39600 | P33: 7 | Q33: 1 | R33: 3 | S33: 0 | T33: 12 | AH33: 9500250551 | AI33: SENT | AJ33: 27
A34: 46063.689 | B34: selvapreethi8@gmail.com | C34: Selvakumar Muthusamy | D34: MALE | E34: S..G.TEACHER | F34: CNLPS1925G | G34: 0 | H34: 9787762252 | I34: P.U.MIDDLE SCHOOL, | J34: Melaiyanpatti | K34: BEO,THIRUPATHUR | L34: 2000 | M34: 0 | N34: 3000 | O34: 35100 | P34: 7 | Q34: 0 | R34: 1 | S34: 0 | T34: 0 | AH34: 9787762252 | AI34: SENT | AJ34: 25
A35: 46063.934 | B35: rksirbsm@gmail.com | C35: SARANYA.K | D35: FEMALE | E35: S..G.TEACHER | F35: EICPS0563N | G35: CHEAO6504B | H35: 7402496307 | I35: P.U.PRIMARY SCHOOL, | J35: Udaiyakulampudur | K35: BEO OFFICE THOTTIYAM | L35: 2000 | M35: 1000 | N35: 3000 | O35: 32100 | P35: 10 | Q35: 0 | R35: 3 | S35: 0 | T35: 1 | AG35: 0 | AH35: 9842320180 | AI35: SENT | AJ35: 27
A36: 46070.529 | B36: kanniyappanezhumalai@gmail.com | C36: SUMATHI.E | D36: FEMALE | E36: S..G.TEACHER | F36: FMPPS9286C | G36: CHEA144448A | H36: 9677692938 | I36: P.U.PRIMARY SCHOOL, | J36: PUPS METTUNATHAM | K36: BEO ,MAILAM | L36: 2000 | M36: 1000 | N36: 3000 | O36: 28500 | P36: 7 | Q36: 0 | R36: 3 | S36: 0 | T36: 10 | U36: 18679 | V36: 4 | W36: 0 | X36: 0 | Y36: 0 | Z36: 0 | AA36: 0 | AB36: 0 | AC36: 0 | AD36: 0 | AE36: 0 | AF36: 0 | AG36: 0 | AH36: 9944226178 | AI36: SENT | AJ36: 27
A37: 46067.412 | B37: rejulawilson@gmail.com | C37: KAVITHA J | D37: FEMALE | E37: S..G.TEACHER | F37: AGNPR13493 | G37: CMBG07083G | H37: 9715249332 | I37: GOVT.HIGH SCHOOL, | J37: KUNIYAMUTHUR | K37: GHS | L37: 2000 | M37: 0 | N37: 3000 | O37: 67500 | P37: 4 | Q37: 2 | R37: 5 | S37: 0 | T37: 0 | U37: 0 | V37: 0 | W37: 0 | X37: 7652 | Y37: 7954 | Z37: 7954 | AA37: 7954 | AB37: 7954 | AC37: 7954 | AD37: 7953 | AE37: 8604 | AF37: 8604 | AG37: 8838 | AH37: 9715249332 | AI37: SENT | AJ37: 0
A38: 46079.469 | B38: emm.kannan86@gmail.com | C38: Kannan M | D38: MALE | E38: S..G.TEACHER | F38: Bwxpk2482a | G38: MRIA01163B | H38: 9688909764 | I38: P.U.PRIMARY SCHOOL, | J38: SEVALKULAM | K38: BEO OFFICE, KURUVIKULAM | L38: 2000 | M38: 0 | N38: 3000 | O38: 39600 | P38: 7 | Q38: 0 | R38: 3 | S38: 2500 | T38: 0 | U38: 0 | V38: 0 | W38: 0 | X38: 0 | Y38: 0 | Z38: 0 | AH38: 8098448008 | AI38: SENT | AJ38: 4
A39: 46073.867 | B39: emm.saravanakannan86@gmail.com | C39: REBECCA C | D39: FEMALE | E39: S..G.TEACHER | F39: AUDPR2240N | G39: MRIA01163B | H39: 9688909764 | I39: P.U.PRIMARY SCHOOL, | J39: SEVALKULAM | K39: BEO OFFICE, KURUVIKULAM | L39: 2000 | M39: 1000 | N39: 3000 | O39: 39600 | P39: 7 | Q39: 0 | R39: 3 | S39: 0 | T39: 10 | U39: 0 | V39: 0 | AH39: 8098448008 | AI39: SENT | AJ39: 6

Sheet INPUT
A1: DETAILS | B1: FILL THE COLUMNS ONLY | D1: DETAILS | E1: FILL COLUMNS | F1: MONTH | G1: IT WITH CESS
A2: NAME OF THE EMPLOYEE | B2: Kannan M | D2: MARCH BASIC PAY | E2: 39600 | F2: MARCH | G2: 0
A3: SEX OF THE EMPLOYEE | B3: MALE | D3: INCREMENT MONTH | E3: 7 | F3: APRIL | G3: 0
A4: DESIGNATION OF THE EMPLOYEE | B4: S..G.TEACHER | D4: PP for S.G. Trs | E4: 2000 | F4: MAY | G4: 0
A5: PAN NUMBER OF THE EMPLOYEE | B5: Bwxpk2482a | D5: PONGAL BONUS | E5: 3000 | F5: JUNE | G5: 0 | H5: 3000
A6: TAN NUMBER OF THE EMPLOYEE | B6: MRIA01163B | D6: SURRENDER MONTH (0,10,11,12,1) | E6: 0 | F6: JULY | G6: 0
A7: MOBILE NUMBER | B7: 9688909764 | D7: IF HRA 850, PUT -1 IF HRA 2200, PUT -2 IF HRA 3200, PUT -3 IF HRA 4300, PUT -4 IF HRA 8300 TYPE- 5 | E7: 3 | F7: AUGUST | G7: 0
A8: SCHOOL NAME OF THE EMPLOYEE | B8: P.U.PRIMARY SCHOOL, | F8: SEPTEMBER | G8: 0
A9: SCHOOL TYPE OF THE EMPLOYEE | F9: OCTOBER | G9: 0
A10: PLACE OF THE SCHOOL | B10: SEVALKULAM | D10: IF CCA (Except Chennai) -1 IF CCA for CHENNAI - 2 | E10: 0 | F10: NOVEMBER | G10: 0
A11: OFFICE OF THE EMPLOYEE | B11: BEO OFFICE, KURUVIKULAM | D11: DA ARREARS - 1 | F11: DECEMBER | G11: 0
A12: FINANCIAL YEAR | B12: 2025 | C12: =B12+1 -> 2026 | D12: DA ARREARS - 2 | F12: JANUARY | G12: 0
A13: ASSESSMENT YEAR | B13: 2026 | C13: =B13+1 -> 2027 | D13: NEXT BASIC | F13: Selection / Special Grade arrears | G13: 0 | H13: =ROUND(E2*3%,-2) -> 1200 | K13: https://forms.gle/YD9XKzXddFjjTuKXA
A14: pp surrender | D14: Spl. abled Persons trans. allowance | E14: 2500 | F14: Selection / Special Grade New pay | G14: 0
D15: Stricke month | E15: 1 | F15: Strick days | G15: 4

Sheet 1 PAGE
A1: INCOME TAX CALCULATION STATEMENT | AA1: TESTF | AF1: FOUR TYPES OF HOUSE RENT ALLOWANCES | AX1: Chennai
A2: ="FOR THE FINANCIAL YEAR "&INPUT!B12&"- "&INPUT!C12&" AND THE ASSESSMENT YEAR "&INPUT!B13&"- "&INPUT!C13&"" -> FOR THE FINANCIAL YEAR 2025- 2026 AND THE ASSESSMENT YEAR 2026- 2027 | Q2: ="PAY DRAWN PARTICULARS FOR THE FINANCE YEAR OF "&INPUT!B12&" - "&INPUT!C12&"" -> PAY DRAWN PARTICULARS FOR THE FINANCE YEAR OF 2025 - 2026 | AD2: Increments | AE2: DA | AF2: HRA | AG2: 13601 | AH2: 300 | AJ2: 13601 | AK2: 450 | AM2: 13601 | AN2: 700 | AP2: 13601 | AQ2: 1000 | AS2: 13601 | AT2: 150 | BA2: INCOME TAX CALCULATION
A3: NAME | F3: =INPUT!B2 -> Kannan M | K3: PAN NUNBER | N3: =INPUT!B5 -> Bwxpk2482a | Q3: MONTH | R3: DA | T3: BASIC PAY | U3: DA | V3: OA | W3: HRA | X3: CCA | Y3: MA | Z3: Spl. abled Person Allowance | AA3: GROSS | AB3: IT Ded | AD3: APRIL | AG3: 17201 | AH3: 350 | AJ3: 17201 | AK3: 500 | AM3: 17201 | AN3: 800 | AP3: 17201 | AQ3: 1200 | AS3: 17201 | AT3: 1800 | BA3: =O11 -> 737104
A4: DESIGNATION | F4: =INPUT!B4 -> S..G.TEACHER | K4: TAN NUMBER | N4: =INPUT!B6 -> MRIA01163B | AD4: =ROUND(T5*3%,-2) -> 1200 | AG4: 21001 | AH4: 400 | AJ4: 21001 | AK4: 700 | AM4: 21001 | AN4: 1000 | AP4: 21001 | AQ4: 1400 | AS4: 21001 | AT4: 2100 | AZ4: 360 | BA4: =BA3-400000 -> 337104 | BB4: =IF(BA4>=0,BA4,0) -> 337104 | BC4: =IF(BB4>=400000, 400000,BB4) -> 337104 | BD4: =IF(BB4>0,BC4,BB4) -> 337104
A5: SEX | F5: =INPUT!B3 -> MALE | K5: CELL No. | N5: =INPUT!B7 -> 9688909764 | Q5: ="MAR - "&INPUT!B12&"" -> MAR - 2025 | R5: 53 | S5: % | T5: =INPUT!E2 -> 39600 | U5: =AE5 -> 20988 | V5: =INPUT!E4 -> 2000 | W5: =IF(INPUT!E7=1,AF5,IF(INPUT!E7=2,AI5,IF(INPUT!E7=3,AL5,IF(INPUT!E7=4,AO5,IF(INPUT!E7=5,AR5,0))))) -> 2300 | X5: =IF(INPUT!E10=1,AU5,IF(INPUT!E10=2,AX5,0)) -> 0 | Y5: 300 | Z5: =INPUT!E14 -> 2500 | AA5: =SUM(T5:Z5) -> 67688 | AB5: =INPUT!G2 -> 0 | AE5: =ROUND(T5*R5%,0) -> 20988 | AF5: =VLOOKUP(T5,AG2:AH16,2,1) -> 600 | AG5: 23901 | AH5: 400 | AI5: =VLOOKUP(T5,AJ2:AK16,2,1) -> 1700 | AJ5: 23901 | AK5: 800 | AL5: =VLOOKUP(T5,AM2:AN16,2,1) -> 2300 | AM5: 23901 | AN5: 1200 | AO5: =VLOOKUP(T5,AP2:AQ16,2,1) -> 3000 | AP5: 23901 | AQ5: 1700 | AR5: =VLOOKUP(T5,$AS$2:$AT$17,2,1) -> 4700 | AS5: 23901 | AT5: 2600 | AU5: =VLOOKUP(T5,AV5:AW8,2,1) -> 400 | AV5: 20601 | AW5: 260 | AX5: =VLOOKUP(T5,$AY$4:$AZ$8,2,1) -> 800 | AY5: 20601 | AZ5: 500 | BA5: =BA4-400000 -> -62896 | BB5: =IF(BA5>=0,BA5,0) -> 0 | BC5: =IF(BB5>=400000, 400000,BB5) -> 0 | BD5: =IF(BB5>0,BC5,BB5) -> 0
A6: OFFICE / SCHOOL | F6: =""&INPUT!B8&" "&INPUT!B9&" "&INPUT!B10&" / "&INPUT!B11&"" -> P.U.PRIMARY SCHOOL, SEVALKULAM / BEO OFFICE, KURUVIKULAM | Q6: ="APR - "&INPUT!B12&"" -> APR - 2025 | R6: =R5 -> 53 | S6: % | T6: =IF(AND(INPUT!E3=4,INPUT!G14=4),BL6,IF(INPUT!E3=4,AD6,IF(INPUT!G14=4,BJ6,T5))) -> 39600 | U6: =AE6 -> 20988 | V6: =V5 -> 2000 | W6: =IF(INPUT!E7=1,AF6,IF(INPUT!E7=2,AI6,IF(INPUT!E7=3,AL6,IF(INPUT!E7=4,AO6,IF(INPUT!E7=5,AR5,0))))) -> 2300 | X6: =IF(INPUT!E10=1,AU6,IF(INPUT!E10=2,AX5,0)) -> 0 | Y6: =Y5 -> 300 | Z6: =Z5 -> 2500 | AA6: =SUM(T6:Z6) -> 67688 | AB6: =INPUT!G3 -> 0 | AD6: =T5+AD4 -> 40800 | AE6: =ROUND(T6*R6%,0) -> 20988 | AF6: =VLOOKUP(T6,AG2:AH16,2,1) -> 600 | AG6: 27201 | AH6: 450 | AI6: =VLOOKUP(T6,AJ2:AK16,2,1) -> 1700 | AJ6: 27201 | AK6: 1000 | AL6: =VLOOKUP(T6,AM2:AN16,2,1) -> 2300 | AM6: 27201 | AN6: 1500 | AO6: =VLOOKUP(T6,AP2:AQ16,2,1) -> 3000 | AP6: 27201 | AQ6: 2000 | AR6: =VLOOKUP(T6,$AS$2:$AT$17,2,1) -> 4700 | AS6: 27201 | AT6: 3100 | AU6: =VLOOKUP(T6,AV5:AW8,2,1) -> 400 | AV6: 30801 | AW6: 400 | AX6: =VLOOKUP(T6,$AY$5:$AZ$8,2,1) -> 800 | AY6: 30801 | AZ6: 800 | BA6: =BA5-400000 -> -462896 | BB6: =IF(BA6>=0,BA6,0) -> 0 | BC6: =IF(BB6>=400000, 400000,BB6) -> 0 | BD6: =IF(BB6>0,BC6,BB6) -> 0 | BF6: Apr | BG6: =ROUND(T5*3%,-2) -> 1200 | BH6: =T5+BG6 -> 40800 | BI6: =ROUND(BH6*3%,-2) -> 1200 | BJ6: =BH6+BI6 -> 42000 | BK6: =ROUND(BJ6*3%,-2) -> 1300 | BL6: =BJ6+BK6 -> 43300
A7: 1 | B7: . | C7: GROSS SALARY | N7: Rs. | O7: =AA24 -> 841781 | Q7: ="MAY - "&INPUT!B12&"" -> MAY - 2025 | R7: 55 | S7: % | T7: =IF(INPUT!G14=5,BJ7,T6) -> 39600 | U7: =AE7 -> 21780 | V7: =V6 -> 2000 | W7: =IF(INPUT!E7=1,AF7,IF(INPUT!E7=2,AI7,IF(INPUT!E7=3,AL7,IF(INPUT!E7=4,AO7,IF(INPUT!E7=5,AR5,0))))) -> 2300 | X7: =IF(INPUT!E10=1,AU7,IF(INPUT!E10=2,AX5,0)) -> 0 | Y7: =Y6 -> 300 | Z7: =Z6 -> 2500 | AA7: =SUM(T7:Z7) -> 68480 | AB7: =INPUT!G4 -> 0 | AD7: JULY | AE7: =ROUND(T7*R7%,0) -> 21780 | AF7: =VLOOKUP(T7,AG2:AH16,2,1) -> 600 | AG7: 30601 | AH7: 500 | AI7: =VLOOKUP(T7,AJ2:AK16,2,1) -> 1700 | AJ7: 30601 | AK7: 1200 | AL7: =VLOOKUP(T7,AM2:AN16,2,1) -> 2300 | AM7: 30601 | AN7: 1700 | AO7: =VLOOKUP(T7,AP2:AQ16,2,1) -> 3000 | AP7: 30601 | AQ7: 2300 | AR7: =VLOOKUP(T7,$AS$2:$AT$17,2,1) -> 4700 | AS7: 30601 | AT7: 3600 | AU7: =VLOOKUP(T7,AV5:AW8,2,1) -> 400 | AV7: 41101 | AW7: 720 | AX7: =VLOOKUP(T7,$AY$5:$AZ$8,2,1) -> 800 | AY7: 41101 | AZ7: 1200 | BA7: =BA6-400000 -> -862896 | BB7: =IF(BA7>=0,BA7,0) -> 0 | BC7: =IF(BB7>=400000, 400000,BB7) -> 0 | BD7: =IF(BB7>0,BC7,BB7) -> 0 | BF7: May | BG7: =ROUND(T6*3%,-2) -> 1200 | BH7: =T6+BG7 -> 40800 | BI7: =ROUND(BH7*3%,-2) -> 1200 | BJ7: =BH7+BI7 -> 42000
A8: 2 | B8: . | C8: STANDARD DEDECTION | K8: Rs. | L8: 75000 | Q8: ="JUN - "&INPUT!B12&"" -> JUN - 2025 | R8: =R7 -> 55 | S8: % | T8: =IF(INPUT!G14=6,BJ8,T7) -> 39600 | U8: =AE8 -> 21780 | V8: =V7 -> 2000 | W8: =IF(INPUT!E7=1,AF8,IF(INPUT!E7=2,AI8,IF(INPUT!E7=3,AL8,IF(INPUT!E7=4,AO8,IF(INPUT!E7=5,AR5,0))))) -> 2300 | X8: =IF(INPUT!E10=1,AU8,IF(INPUT!E10=2,AX5,0)) -> 0 | Y8: =Y7 -> 300 | Z8: =Z7 -> 2500 | AA8: =SUM(T8:Z8) -> 68480 | AB8: =INPUT!G5 -> 0 | AD8: =ROUND(T8*3%,-2) -> 1200 | AE8: =ROUND(T8*R8%,0) -> 21780 | AF8: =VLOOKUP(T8,AG2:AH16,2,1) -> 600 | AG8: 35401 | AH8: 550 | AI8: =VLOOKUP(T8,AJ2:AK16,2,1) -> 1700 | AJ8: 35401 | AK8: 1500 | AL8: =VLOOKUP(T8,AM2:AN16,2,1) -> 2300 | AM8: 35401 | AN8: 1800 | AO8: =VLOOKUP(T8,AP2:AQ16,2,1) -> 3000 | AP8: 35401 | AQ8: 2600 | AR8: =VLOOKUP(T8,$AS$2:$AT$17,2,1) -> 4700 | AS8: 35401 | AT8: 4200 | AU8: =VLOOKUP(T8,AV5:AW8,2,1) -> 400 | AX8: =VLOOKUP(T8,$AY$5:$AZ$8,2,1) -> 800 | BA8: =BA7-400000 -> -1262896 | BB8: =IF(BA8>=0,BA8,0) -> 0 | BC8: =IF(BB8>=400000, 400000,BB8) -> 0 | BD8: =IF(BB8>0,BC8,BB8) -> 0 | BF8: Jun | BG8: =ROUND(T7*3%,-2) -> 1200 | BH8: =T7+BG8 -> 40800 | BI8: =ROUND(BH8*3%,-2) -> 1200 | BJ8: =BH8+BI8 -> 42000
A9: 3 | B9: . | C9: Specially abled Persons trans. allowance | K9: Rs. | L9: =Z24 -> 29677 | Q9: ="JULY -"&INPUT!B12&"" -> JULY -2025 | R9: 55 | S9: % | T9: =IF(AND(INPUT!E3=7,INPUT!G14=7),BL9,IF(INPUT!E3=7,AD9,IF(INPUT!G14=7,BJ9,T8))) -> 40800 | U9: =AE9 -> 22440 | V9: =V8 -> 2000 | W9: =IF(INPUT!E7=1,AF9,IF(INPUT!E7=2,AI9,IF(INPUT!E7=3,AL9,IF(INPUT!E7=4,AO9,IF(INPUT!E7=5,AR5,0))))) -> 2300 | X9: =IF(INPUT!E10=1,AU9,IF(INPUT!E10=2,AX5,0)) -> 0 | Y9: =Y8 -> 300 | Z9: =Z8 -> 2500 | AA9: =SUM(T9:Z9) -> 70340 | AB9: =INPUT!G6 -> 0 | AD9: =T8+AD8 -> 40800 | AE9: =ROUND(T9*R9%,0) -> 22440 | AF9: =VLOOKUP(T9,AG2:AH16,2,1) -> 600 | AG9: 37301 | AH9: 600 | AI9: =VLOOKUP(T9,AJ2:AK16,2,1) -> 1700 | AJ9: 37301 | AK9: 1700 | AL9: =VLOOKUP(T9,AM2:AN16,2,1) -> 2300 | AM9: 37301 | AN9: 2300 | AO9: =VLOOKUP(T9,AP2:AQ16,2,1) -> 3000 | AP9: 37301 | AQ9: 3000 | AR9: =VLOOKUP(T9,$AS$2:$AT$17,2,1) -> 4700 | AS9: 37301 | AT9: 4700 | AU9: =VLOOKUP(T9,AV6:AW8,2,1) -> 400 | AX9: =VLOOKUP(T9,$AY$5:$AZ$8,2,1) -> 800 | BA9: =BA8-400000 -> -1662896 | BB9: =IF(BA9>=0,BA9,0) -> 0 | BC9: =IF(BB9>=400000, 400000,BB9) -> 0 | BD9: =IF(BB9>0,BC9,BB9) -> 0 | BF9: Jul | BG9: =ROUND(T8*3%,-2) -> 1200 | BH9: =T8+BG9 -> 40800 | BI9: =ROUND(BH9*3%,-2) -> 1200 | BJ9: =BH9+BI9 -> 42000 | BK9: =ROUND(BJ9*3%,-2) -> 1300 | BL9: =BJ9+BK9 -> 43300
A10: 4 | B10: . | C10: TOTAL DEDUCTION | K10: Rs. | L10: =L8+L9 -> 104677 | N10: Rs. | O10: =L10 -> 104677 | Q10: ="AUG - "&INPUT!B12&"" -> AUG - 2025 | R10: =R9 -> 55 | S10: % | T10: =IF(INPUT!G14=8,BJ10,T9) -> 40800 | U10: =AE10 -> 22440 | V10: =V9 -> 2000 | W10: =IF(INPUT!E7=1,AF10,IF(INPUT!E7=2,AI10,IF(INPUT!E7=3,AL10,IF(INPUT!E7=4,AO10,IF(INPUT!E7=5,AR5,0))))) -> 2300 | X10: =IF(INPUT!E10=1,AU10,IF(INPUT!E10=2,AX5,0)) -> 0 | Y10: =Y9 -> 300 | Z10: =Z9 -> 2500 | AA10: =SUM(T10:Z10) -> 70340 | AB10: =INPUT!G7 -> 0 | AD10: OCTOBER | AE10: =ROUND(T10*R10%,0) -> 22440 | AF10: =VLOOKUP(T10,AG2:AH16,2,1) -> 600 | AG10: 41101 | AH10: 650 | AI10: =VLOOKUP(T10,AJ2:AK16,2,1) -> 1700 | AJ10: 41101 | AK10: 1900 | AL10: =VLOOKUP(T10,AM2:AN16,2,1) -> 2300 | AM10: 41101 | AN10: 2600 | AO10: =VLOOKUP(T10,AP2:AQ16,2,1) -> 3000 | AP10: 41101 | AQ10: 3300 | AR10: =VLOOKUP(T10,$AS$2:$AT$17,2,1) -> 4700 | AS10: 41101 | AT10: 5200 | AU10: =VLOOKUP(T10,AV6:AW8,2,1) -> 400 | AX10: =VLOOKUP(T10,$AY$5:$AZ$8,2,1) -> 800 | BA10: =BA9-400000 -> -2062896 | BF10: Aug | BG10: =ROUND(T9*3%,-2) -> 1200 | BH10: =T9+BG10 -> 42000 | BI10: =ROUND(BH10*3%,-2) -> 1300 | BJ10: =BH10+BI10 -> 43300
A11: 5 | B11: . | C11: TOTAL TAXABLE SALARY INCOME [1-4] | N11: Rs. | O11: =O7-O10 -> 737104 | Q11: ="SEP - "&INPUT!B12&"" -> SEP - 2025 | R11: =R10 -> 55 | S11: % | T11: =IF(INPUT!G14=9,BJ11,T10) -> 40800 | U11: =AE11 -> 22440 | V11: =V10 -> 2000 | W11: =IF(INPUT!E7=1,AF11,IF(INPUT!E7=2,AI11,IF(INPUT!E7=3,AL11,IF(INPUT!E7=4,AO11,IF(INPUT!E7=5,AR5,0))))) -> 2300 | X11: =IF(INPUT!E10=1,AU11,IF(INPUT!E10=2,AX5,0)) -> 0 | Y11: =Y10 -> 300 | Z11: =Z10 -> 2500 | AA11: =SUM(T11:Z11) -> 70340 | AB11: =INPUT!G8 -> 0 | AD11: =ROUND(T11*3%,-2) -> 1200 | AE11: =ROUND(T11*R11%,0) -> 22440 | AF11: =VLOOKUP(T11,AG2:AH16,2,1) -> 600 | AG11: 44501 | AH11: 650 | AI11: =VLOOKUP(T11,AJ2:AK16,2,1) -> 1700 | AJ11: 44501 | AK11: 2000 | AL11: =VLOOKUP(T11,AM2:AN16,2,1) -> 2300 | AM11: 44501 | AN11: 2900 | AO11: =VLOOKUP(T11,AP2:AQ16,2,1) -> 3000 | AP11: 44501 | AQ11: 3600 | AR11: =VLOOKUP(T11,$AS$2:$AT$17,2,1) -> 4700 | AS11: 44501 | AT11: 5700 | AU11: =VLOOKUP(T11,AV5:AW8,2,1) -> 400 | AX11: =VLOOKUP(T11,$AY$5:$AZ$8,2,1) -> 800 | BF11: Sep | BG11: =ROUND(T10*3%,-2) -> 1200 | BH11: =T10+BG11 -> 42000 | BI11: =ROUND(BH11*3%,-2) -> 1300 | BJ11: =BH11+BI11 -> 43300
A12: TABLE - 2 TAX CALCULATION | Q12: ="OCT - "&INPUT!B12&"" -> OCT - 2025 | R12: =R11 -> 55 | S12: % | T12: =IF(AND(INPUT!E3=10,INPUT!G14=10),BL12,IF(INPUT!E3=10,AD12,IF(INPUT!G14=10,BJ12,T11))) -> 40800 | U12: =AE12 -> 22440 | V12: =V11 -> 2000 | W12: =IF(INPUT!E7=1,AF12,IF(INPUT!E7=2,AI12,IF(INPUT!E7=3,AL12,IF(INPUT!E7=4,AO12,IF(INPUT!E7=5,AR5,0))))) -> 2300 | X12: =IF(INPUT!E10=1,AU12,IF(INPUT!E10=2,AX5,0)) -> 0 | Y12: =Y11 -> 300 | Z12: =Z11 -> 2500 | AA12: =SUM(T12:Z12) -> 70340 | AB12: =INPUT!G9 -> 0 | AD12: =T11+AD11 -> 42000 | AE12: =ROUND(T12*R12%,0) -> 22440 | AF12: =VLOOKUP(T12,AG2:AH16,2,1) -> 600 | AG12: 50201 | AH12: 700 | AI12: =VLOOKUP(T12,AJ2:AK16,2,1) -> 1700 | AJ12: 50201 | AK12: 2200 | AL12: =VLOOKUP(T12,AM2:AN16,2,1) -> 2300 | AM12: 50201 | AN12: 3100 | AO12: =VLOOKUP(T12,AP2:AQ16,2,1) -> 3000 | AP12: 50201 | AQ12: 3800 | AR12: =VLOOKUP(T12,$AS$2:$AT$17,2,1) -> 4700 | AS12: 50201 | AT12: 6200 | AU12: =VLOOKUP(T12,AV6:AW8,2,1) -> 400 | AX12: =VLOOKUP(T12,$AY$5:$AZ$8,2,1) -> 800 | BF12: Oct | BG12: =ROUND(T11*3%,-2) -> 1200 | BH12: =T11+BG12 -> 42000 | BI12: =ROUND(BH12*3%,-2) -> 1300 | BJ12: =BH12+BI12 -> 43300 | BK12: =ROUND(BJ12*3%,-2) -> 1300 | BL12: =BJ12+BK12 -> 44600
A13: TAXABLE INCOME | O13: =O11 -> 737104 | Q13: ="NOV - "&INPUT!B12&"" -> NOV - 2025 | R13: 58 | S13: % | T13: =T43 -> 40800 | U13: =U43 -> 23664 | V13: =V43 -> 2000 | W13: =W43 -> 2300 | X13: =X43 -> 0 | Y13: =Y43 -> 300 | Z13: =Z43 -> 2500 | AA13: =SUM(T13:Z13) -> 71564 | AB13: =INPUT!G10 -> 0 | AD13: JANUARY | AE13: =ROUND(T13*R13%,0) -> 23664 | AF13: =VLOOKUP(T13,AG2:AH16,2,1) -> 600 | AG13: 51601 | AH13: 750 | AI13: =VLOOKUP(T13,AJ2:AK16,2,1) -> 1700 | AJ13: 51601 | AK13: 2200 | AL13: =VLOOKUP(T13,AM2:AN16,2,1) -> 2300 | AM13: 51601 | AN13: 3200 | AO13: =VLOOKUP(T13,AP2:AQ16,2,1) -> 3000 | AP13: 51601 | AQ13: 4100 | AR13: =VLOOKUP(T13,$AS$2:$AT$17,2,1) -> 4700 | AS13: 51601 | AT13: 6800 | AU13: =VLOOKUP(T13,AV6:AW8,2,1) -> 400 | AX13: =VLOOKUP(T13,$AY$5:$AZ$8,2,1) -> 800 | BF13: Nov | BG13: =ROUND(T12*3%,-2) -> 1200 | BH13: =T12+BG13 -> 42000 | BI13: =ROUND(BH13*3%,-2) -> 1300 | BJ13: =BH13+BI13 -> 43300
A14: (i) Upto 400000 /- | G14: =IF(O13>=0,O13,0) -> 737104 | J14: 400000 | O14: NIL | Q14: ="DEC - "&INPUT!B12&"" -> DEC - 2025 | R14: =R13 -> 58 | S14: % | T14: =IF(INPUT!G14=12,BJ14,T38) -> 40800 | U14: =AE14 -> 23664 | V14: =V12 -> 2000 | W14: =IF(INPUT!E7=1,AF14,IF(INPUT!E7=2,AI14,IF(INPUT!E7=3,AL14,IF(INPUT!E7=4,AO14,IF(INPUT!E7=5,AR5,0))))) -> 2300 | X14: =IF(INPUT!E10=1,AU14,IF(INPUT!E10=2,AX5,0)) -> 0 | Y14: =Y12 -> 300 | Z14: =Z13 -> 2500 | AA14: =SUM(T14:Z14) -> 71564 | AB14: =INPUT!G11 -> 0 | AD14: =ROUND(T14*3%,-2) -> 1200 | AE14: =ROUND(T14*R14%,0) -> 23664 | AF14: =VLOOKUP(T14,AG2:AH16,2,1) -> 600 | AG14: 54001 | AH14: 800 | AI14: =VLOOKUP(T14,AJ2:AK16,2,1) -> 1700 | AJ14: 54001 | AK14: 2200 | AL14: =VLOOKUP(T14,AM2:AN16,2,1) -> 2300 | AM14: 54001 | AN14: 3200 | AO14: =VLOOKUP(T14,AP2:AQ16,2,1) -> 3000 | AP14: 54001 | AQ14: 4300 | AR14: =VLOOKUP(T14,$AS$2:$AT$17,2,1) -> 4700 | AS14: 54001 | AT14: 7300 | AU14: =VLOOKUP(T14,AV6:AW8,2,1) -> 400 | AX14: =VLOOKUP(T14,$AY$5:$AZ$8,2,1) -> 800 | BF14: Dec | BG14: =ROUND(T13*3%,-2) -> 1200 | BH14: =T13+BG14 -> 42000 | BI14: =ROUND(BH14*3%,-2) -> 1300 | BJ14: =BH14+BI14 -> 43300
A15: (ii) 400001 - 800000 5% | G15: =BB4 -> 337104 | J15: =IF(BB4>400000,BC4,BD4) -> 337104 | O15: =ROUND(J15*5%,0) -> 16855 | Q15: ="JAN - "&INPUT!B13&"" -> JAN - 2026 | R15: =R14 -> 58 | S15: % | T15: =T47 -> 35535 | U15: =U47 -> 20611 | V15: =V47 -> 1742 | W15: =W47 -> 2003 | X15: =X47 -> 0 | Y15: =Y47 -> 261 | Z15: =Z47 -> 2177 | AA15: =SUM(T15:Z15) -> 62329 | AB15: =INPUT!G12 -> 0 | AD15: =T14+AD14 -> 42000 | AE15: =ROUND(T45*R15%,0) -> 23664 | AF15: =VLOOKUP(T45,AG2:AH16,2,1) -> 600 | AG15: 55501 | AH15: 850 | AI15: =VLOOKUP(T45,AJ2:AK16,2,1) -> 1700 | AJ15: 55501 | AK15: 2200 | AL15: =VLOOKUP(T45,AM2:AN16,2,1) -> 2300 | AM15: 55501 | AN15: 3200 | AO15: =VLOOKUP(T45,AP2:AQ16,2,1) -> 3000 | AP15: 55501 | AQ15: 4300 | AR15: =VLOOKUP(T45,$AS$2:$AT$17,2,1) -> 4700 | AS15: 55501 | AT15: 7500 | AU15: =VLOOKUP(T45,AV6:AW8,2,1) -> 400 | AX15: =VLOOKUP(T45,$AY$5:$AZ$8,2,1) -> 800 | BF15: Jan | BG15: =ROUND(T14*3%,-2) -> 1200 | BH15: =T14+BG15 -> 42000 | BI15: =ROUND(BH15*3%,-2) -> 1300 | BJ15: =BH15+BI15 -> 43300 | BK15: =ROUND(BJ15*3%,-2) -> 1300 | BL15: =BJ15+BK15 -> 44600
A16: (iii) 800001 - 1200000 10% | G16: =BB5 -> 0 | J16: =IF(BB5>400000,BC5,BD5) -> 0 | O16: =ROUND(J16*10%,0) -> 0 | Q16: ="FEB - "&INPUT!B13&"" -> FEB - 2026 | R16: =R15 -> 58 | S16: % | T16: =T34 -> 40800 | U16: =U34 -> 23664 | V16: =V34 -> 2000 | W16: =W34 -> 2300 | X16: =X34 -> 0 | Y16: =Y34 -> 300 | Z16: =Z34 -> 2500 | AA16: =SUM(T16:Z16) -> 71564 | AE16: =ROUND(T16*R16%,0) -> 23664 | AF16: =VLOOKUP(T30,AG2:AH16,2,1) -> 600 | AG16: 56901 | AH16: 850 | AI16: =VLOOKUP(T30,AJ2:AK16,2,1) -> 1700 | AJ16: 56901 | AK16: 2200 | AL16: =VLOOKUP(T30,AM2:AN16,2,1) -> 2300 | AM16: 56901 | AN16: 3200 | AO16: =VLOOKUP(T30,AP2:AQ16,2,1) -> 3000 | AP16: 56901 | AQ16: 4300 | AR16: =VLOOKUP(T30,$AS$2:$AT$17,2,1) -> 4700 | AS16: 56901 | AT16: 7800 | AU16: =VLOOKUP(T30,AV6:AW8,2,1) -> 400 | AX16: =VLOOKUP(T16,$AY$5:$AZ$8,2,1) -> 800 | BF16: Feb | BG16: =ROUND(T15*3%,-2) -> 1100 | BH16: =T15+BG16 -> 36635 | BI16: =ROUND(BH16*3%,-2) -> 1100 | BJ16: =BH16+BI16 -> 37735
A17: (iv) 1200001 - 1600000 15% | G17: =BB6 -> 0 | J17: =IF(BB6>400000,BC6,BD6) -> 0 | O17: =ROUND(J17*15%,0) -> 0 | Q17: TOTAL | T17: =SUM(T5:T16) -> 479535 | U17: =SUM(U5:U16) -> 266899 | V17: =SUM(V5:V16) -> 23742 | W17: =SUM(W5:W16) -> 27303 | X17: =SUM(X5:X16) -> 0 | Y17: =SUM(Y5:Y16) -> 3561 | Z17: =SUM(Z5:Z16) -> 29677 | AA17: =SUM(AA5:AA16) -> 830717 | AB17: =SUM(AB5:AB16) -> 0 | AR17: =VLOOKUP(T17,$AS$2:$AT$17,2,1) -> 8300 | AS17: 64201 | AT17: 8300
A18: (v) 1600001 - 2000000 20% | G18: =BB7 -> 0 | J18: =IF(BB7>400000,BC7,BD7) -> 0 | O18: =ROUND(J18*20%,0) -> 0 | Q18: BONUS | AA18: =INPUT!E5 -> 3000 | AD18: DA-1
A19: (vi) 2000001 - 2400000 25% | G19: =BB8 -> 0 | J19: =IF(BB8>400000,BC8,BD8) -> 0 | O19: =ROUND(J19*25%,0) -> 0 | Q19: DA Arrears 1 | U19: =AG21 -> 3168 | AA19: =SUM(T19:Y19) -> 3168 | AD19: =ROUND(T5*55%,0) -> 21780 | AE19: =ROUND(T5*53%,0) -> 20988 | AF19: =AD19-AE19 -> 792 | AG19: =AF19*3 -> 2376
A20: (vii) 2400004 and above 30% | G20: =BB9 -> 0 | J20: =IF(BB9>400000,BC9,BD9) -> 0 | O20: =ROUND(J20*30%,0) -> 0 | Q20: DA Arrears 2 | U20: =IF(INPUT!E6=10,'1 PAGE'!AI26,'1 PAGE'!AG26) -> 4896 | AA20: =SUM(T20:Y20) -> 4896 | AD20: =ROUND(T6*55%,0) -> 21780 | AE20: =ROUND(T6*53%,0) -> 20988 | AF20: =AD20-AE20 -> 792 | AG20: =AF20*1 -> 792
J21: TOTAL TAX | O21: =O15+O16+O17+O18+O19+O20 -> 16855 | Q21: Surrender | T21: =IF(INPUT!E6=10,AH29,IF(INPUT!E6=11,AH32,IF(INPUT!E6=12,AH32,IF(INPUT!E6=1,AH35,0)))) -> 0 | U21: =IF(INPUT!E6=10,AI29,IF(INPUT!E6=11,AI32,IF(INPUT!E6=12,AI32,IF(INPUT!E6=1,AI35,0)))) -> 0 | V21: =INPUT!B14 | W21: =IF(INPUT!E6=10,AK29,IF(INPUT!E6=11,AK32,IF(INPUT!E6=12,AK32,IF(INPUT!E6=1,AK35,0)))) -> 0 | X21: =IF(INPUT!E6=10,AL29,IF(INPUT!E6=11,AL32,IF(INPUT!E6=12,AL32,IF(INPUT!E6=1,AL35,0)))) -> 0 | Y21: 0 | AA21: =SUM(T21:Y21) -> 0 | AC21: =O21-O23 -> 16855 | AG21: =AG19+AG20 -> 3168
A22: 7 | B22: . | C22: Less : Tax Rebate U/S 87A (Marginal Relief) | O22: =IF(AC21>0,AC21,0) -> 16855 | Q22: Prom/Slec/spl Gr Arr | T22: =INPUT!G13 -> 0 | AA22: =SUM(T22:Y22) -> 0
C23: Marginal Relief Tax Upto Rs.70500/- | N23: Rs. | O23: =IF(AF31>0,AF31,0) -> 0 | AD23: DA-2
A24: 8 | B24: . | C24: ADD : EDUCATIONAL CESS (4%) | H24: =IF(O23>0,O23,O21) -> 16855 | J24: * | K24: 0.04 | N24: Rs. | O24: =AE36 -> 0 | Q24: TOTAL | T24: =SUM(T17:T23) -> 479535 | U24: =SUM(U17:U23) -> 274963 | V24: =SUM(V17:V23) -> 23742 | W24: =SUM(W17:W23) -> 27303 | Y24: =SUM(Y17:Y23) -> 3561 | Z24: =SUM(Z17:Z23) -> 29677 | AA24: =SUM(AA17:AA23) -> 841781 | AB24: =SUM(AB17:AB23) -> 0 | AD24: =ROUND(T9*58%,0) -> 23664 | AE24: =ROUND(T9*55%,0) -> 22440 | AF24: =AD24-AE24 -> 1224 | AG24: =AF24*3 -> 3672
A25: 9 | B25: . | C25: TAX PAYABLE [6 or 7 + 8] | G25: =IF(O21>70500,O21,O23) -> 0 | H25: + | I25: =O24 -> 0 | N25: Rs. | O25: =G25+I25 -> 0 | AD25: =ROUND(T12*58%,0) -> 23664 | AE25: =ROUND(T12*55%,0) -> 22440 | AF25: =AD25-AE25 -> 1224 | AG25: =AF25*1 -> 1224 | AH25: Surrender DA
A26: 10 | B26: . | C26: Tax so far Deducted (TDS) | G26: ="(Mar -"&INPUT!B12&" - Jan-"&INPUT!B13&" IT Advance Ded.)" -> (Mar -2025 - Jan-2026 IT Advance Ded.) | N26: Rs. | O26: =AB24 -> 0 | AG26: =AG24+AG25 -> 4896 | AH26: =ROUND(AG25/2,0) -> 612 | AI26: =AG26+AH26 -> 5508 | AU26: =ROUND(AU16/2,0) -> 200
A27: 11 | B27: . | C27: ="Balance to be Paid [9-10] in Feb-"&INPUT!B13&" Bill (TDS) """ -> Balance to be Paid [9-10] in Feb-2026 Bill (TDS) " | K27: =AE40 -> 0 + 0 | N27: Rs. | O27: =IF(AM29>0,AM29,0) -> 0 | AH27: Surrender | AU27: =IF(INPUT!E10=1,AU26,0) -> 0
A28: 12 | B28: . | C28: TAX REFUND (TAX OVER DEDUCTION) | N28: Rs. | O28: =-(AM30) -> 0 | Q28: SIGNATURE OF INDIVIDUAL SIGNATURE OF HEAD OFFICE | AD28: Normal Tax | AH28: =T12 -> 40800 | AI28: =U12 -> 22440 | AJ28: =V12 -> 2000 | AK28: =W12 -> 2300 | AL28: =X12 -> 0
AD29: =O13-1200000 -> -462896 | AE29: =O21 -> 16855 | AF29: =IF(AD29<=70500,AD29,AE29) -> -462896 | AH29: =ROUND(AH28/2,0) -> 20400 | AI29: =ROUND(AI28/2,0) -> 11220 | AJ29: =ROUND(AJ28/2,0) -> 1000 | AK29: =ROUND(AK28/2,0) -> 1150 | AL29: =ROUND(AL28/2,0) -> 0 | AM29: =O25-O26 -> 0
T30: =IF(INPUT!G14=2,BJ16,T45) -> 40800 | U30: =AE14 -> 23664 | V30: =V14 -> 2000 | W30: =IF(INPUT!E7=1,AF16,IF(INPUT!E7=2,AI16,IF(INPUT!E7=3,AL16,IF(INPUT!E7=4,AO16,IF(INPUT!E7=5,AR5,0))))) -> 2300 | X30: =IF(INPUT!E10=1,AU15,IF(INPUT!E10=2,AX5,0)) -> 0 | Y30: =Y14 -> 300 | Z30: =Z14 -> 2500 | AA30: =SUM(T30:Z30) -> 71564 | AF30: =IF(AF29<=70500,0,O21) -> 0 | AM30: =IF(AM29<0,AM29,0) -> 0
T31: =IF(INPUT!$G$15=27,ROUND('1 PAGE'!T30/28,0),T30) -> 40800 | U31: =IF(INPUT!$G$15=27,ROUND('1 PAGE'!U30/28,0),U30) -> 23664 | V31: =IF(INPUT!$G$15=27,ROUND('1 PAGE'!V30/28,0),V30) -> 2000 | W31: =IF(INPUT!$G$15=27,ROUND('1 PAGE'!W30/28,0),W30) -> 2300 | X31: =IF(INPUT!$G$15=27,ROUND('1 PAGE'!X30/28,0),X30) -> 0 | Y31: =IF(INPUT!$G$15=27,ROUND('1 PAGE'!Y30/28,0),Y30) -> 300 | Z31: =IF(INPUT!$G$15=27,ROUND('1 PAGE'!Z30/28,0),Z30) -> 2500 | AA31: =SUM(T31:Z31) -> 71564 | AF31: =IF(AF29>70500,0,AF29) -> -462896 | AH31: =T13 -> 40800 | AI31: =U13 -> 23664 | AJ31: =V13 -> 2000 | AK31: =W13 -> 2300 | AL31: =X13 -> 0
T32: =T30-T31 -> 0 | U32: =U30-U31 -> 0 | V32: =V30-V31 -> 0 | W32: =W30-W31 -> 0 | X32: =X30-X31 -> 0 | Y32: =Y30-Y31 -> 0 | Z32: =Z30-Z31 -> 0 | AA32: =SUM(T32:Z32) -> 0 | AH32: =ROUND(AH31/2,0) -> 20400 | AI32: =ROUND(AI31/2,0) -> 11832 | AJ32: =ROUND(AJ31/2,0) -> 1000 | AK32: =ROUND(AK31/2,0) -> 1150 | AL32: =ROUND(AL31/2,0) -> 0
T33: =IF(INPUT!$G$15=27,'1 PAGE'!T32,0) -> 0 | U33: =IF(INPUT!$G$15=27,'1 PAGE'!U32,0) -> 0 | V33: =IF(INPUT!$G$15=27,'1 PAGE'!V32,0) -> 0 | W33: =IF(INPUT!$G$15=27,'1 PAGE'!W32,0) -> 0 | X33: =IF(INPUT!$G$15=27,'1 PAGE'!X32,0) -> 0 | Y33: =IF(INPUT!$G$15=27,'1 PAGE'!Y32,0) -> 0 | Z33: =IF(INPUT!$G$15=27,'1 PAGE'!Z32,0) -> 0 | AA33: =SUM(T33:Z33) -> 0 | AD33: Marginal Relief Tax
T34: =IF(INPUT!$G$15=27,'1 PAGE'!T33,'1 PAGE'!T30) -> 40800 | U34: =IF(INPUT!$G$15=27,'1 PAGE'!U33,'1 PAGE'!U30) -> 23664 | V34: =IF(INPUT!$G$15=27,'1 PAGE'!V33,'1 PAGE'!V30) -> 2000 | W34: =IF(INPUT!$G$15=27,'1 PAGE'!W33,'1 PAGE'!W30) -> 2300 | X34: =IF(INPUT!$G$15=27,'1 PAGE'!X33,'1 PAGE'!X30) -> 0 | Y34: =IF(INPUT!$G$15=27,'1 PAGE'!Y33,'1 PAGE'!Y30) -> 300 | Z34: =IF(INPUT!$G$15=27,'1 PAGE'!Z33,'1 PAGE'!Z30) -> 2500 | AA34: =SUM(T34:Z34) -> 71564 | AD34: =IF(O21>70500,O21,O23) -> 0 | AH34: =T15 -> 35535 | AI34: =U15 -> 20611 | AJ34: =V15 -> 1742 | AK34: =W15 -> 2003 | AL34: =X15 -> 0
AD35: 0 | AE35: =IF(O21<=70500,AF29,O21) -> -462896 | AH35: =ROUND(AH34/2,0) -> 17768 | AI35: =ROUND(AI34/2,0) -> 10306 | AJ35: =ROUND(AJ34/2,0) -> 871 | AK35: =ROUND(AK34/2,0) -> 1002 | AL35: =ROUND(AL34/2,0) -> 0
AD36: =ROUND(AD34*K24,0) -> 0 | AE36: =IF(AD36>0,AD36,0) -> 0 | AF36: =ROUND(O23*4%,0) -> 0
T37: PAY | U37: DA | V37: OA | W37: HRA | X37: CCA | Y37: MA | Z37: SA | AA37: TOTAL
T38: =IF(INPUT!G14=11,BJ13,T12) -> 40800 | U38: =AE13 -> 23664 | V38: =V12 -> 2000 | W38: =IF(INPUT!E7=1,AF13,IF(INPUT!E7=2,AI13,IF(INPUT!E7=3,AL13,IF(INPUT!E7=4,AO13,IF(INPUT!E7=5,AR5,0))))) -> 2300 | X38: =IF(INPUT!E10=1,AU13,IF(INPUT!E10=2,AX5,0)) -> 0 | Y38: =Y12 -> 300 | Z38: =Z12 -> 2500 | AA38: =SUM(T38:Z38) -> 71564 | AD38: Balance Tax & Cess
T39: =T38/31 -> 1316.129 | U39: =U38/31 -> 763.35484 | V39: =V38/31 -> 64.516129 | W39: =W38/31 -> 74.193548 | X39: =X38/31 -> 0 | Y39: =Y38/31 -> 9.6774194 | Z39: =Z38/31 -> 80.645161 | AA39: =AA38/31 -> 2308.5161 | AD39: =O25-O26 -> 0 | AE39: =ROUND(AD39/104*100,0) -> 0 | AF39: =AD39-AE39 -> 0
T40: =ROUND(T39*INPUT!G15,0) -> 5265 | U40: =ROUND(U39*INPUT!G15,0) -> 3053 | V40: =ROUND(V39*INPUT!G15,0) -> 258 | W40: =ROUND(W39*INPUT!G15,0) -> 297 | X40: =ROUND(X39*INPUT!G15,0) -> 0 | Y40: =ROUND(Y39*INPUT!G15,0) -> 39 | Z40: =ROUND(Z39*INPUT!G15,0) -> 323 | AA40: =ROUND(AA39*INPUT!G15,0) -> 9234 | AE40: =""&AE39&" + "&AF39&"" -> 0 + 0
...
